Workbook
Name ChangeFailed: Raw_Data!$L$2:$L$125
Name DeployDate: Raw_Data!$C$2:$C$125
Name DeploymentId: Raw_Data!$A$2:$A$125
Name FailureCategory: Raw_Data!$M$2:$M$125
Name LeadTimeHours: Raw_Data!$K$2:$K$125
Name Phase: Raw_Data!$D$2:$D$125
Name RecoveryMinutes: Raw_Data!$P$2:$P$125
Name Remediation: Raw_Data!$Q$2:$Q$125
Name ToilMinutes: Raw_Data!$R$2:$R$125

Sheet Summary
A1: HealthQueue DORA Metrics Analysis
A2: 90-day window 01 Jul 2026 - 28 Sep 2026. Built by scripts/build_dora_workbook.py.
A3: SYNTHETIC DATA - simulated deployment records for the assignment. Not real HealthQueue production performance.
A5: DORA metric | B5: Overall (90 d) | C5: Cluster | D5: Last 30 d (3-GitOps) | E5: Cluster | F5: Trend vs. phase 1
A6: Deployment frequency (deploys/day) | B6: =Benchmarks!B20 -> 1.3777778 | C6: =Benchmarks!B21 -> Elite | D6: =Benchmarks!E20 -> 2.0333333 | E6: =Benchmarks!E21 -> Elite | F6: =IF(Metrics!F8>Metrics!D8,"Improving","Worse") -> Improving
A7: Change lead time (median h) | B7: =Benchmarks!B22 -> 12.86 | C7: =Benchmarks!B23 -> Elite | D7: =Benchmarks!E22 -> 7.51 | E7: =Benchmarks!E23 -> Elite | F7: =IF(Metrics!F10<Metrics!D10,"Improving","Worse") -> Improving
A8: Change failure rate | B8: =Benchmarks!B24 -> 0.11290323 | C8: =Benchmarks!B25 -> High value (<=20%) | D8: =Benchmarks!E24 -> 0.081967213 | E8: =Benchmarks!E25 -> Medium value (<=10%) | F8: =IF(Metrics!F13<Metrics!D13,"Improving","Worse") -> Improving
A9: Recovery time (median min) | B9: =Benchmarks!B26 -> 79 | C9: =Benchmarks!B27 -> High / Medium (< 1 day) | D9: =Benchmarks!E26 -> 36 | E9: =Benchmarks!E27 -> Elite | F9: =IF(Metrics!F14<Metrics!D14,"Improving","Worse") -> Improving
A11: Key findings
A12: ="1. Throughput: deployments rose from "&TEXT(Metrics!D8,"0.00")&"/day (manual) to "&TEXT(Metrics!F8,"0.00")&"/day (GitOps); median lead time fell from "&TEXT(Metrics!D10,"0")&" h to "&TEXT(Metrics!F10,"0.0")&" h." -> 1. Throughput: deployments rose from 0.97/day (manual) to 2.03/day (GitOps); median lead time fell from 44 h to 7.5 h.
A13: ="2. Stability: change failure rate went from "&TEXT(Metrics!D13,"0%")&" to "&TEXT(Metrics!F13,"0%")&" and median recovery from "&TEXT(Metrics!D14,"0")&" to "&TEXT(Metrics!F14,"0")&" minutes - speed did not cost stability." -> 2. Stability: change failure rate went from 24% to 8% and median recovery from 224 to 36 minutes - speed did not cost stability.
A14: ="3. Toil: hands-on minutes per deployment dropped "&TEXT(Toil_Reduction!D10,"0%")&" (from "&TEXT(Metrics!D17,"0")&" to "&TEXT(Metrics!F17,"0.0")&" min), saving ~"&TEXT(Toil_Reduction!D11,"0")&" engineer-hours per month at today's volume." -> 3. Toil: hands-on minutes per deployment dropped 92% (from 50 to 4.1 min), saving ~46 engineer-hours per month at today's volume.
A15: 4. Biggest failure sources: configuration error and dependency / migration (each 5 of 14 failures, tied). Target them with policy-as-code checks on manifests/config and migration tests before merge (see Failure_Analysis).
A16: 5. Caveat: phase 2 shows a lower failure rate than phase 3 - with ~30-60 deployments per phase that difference is within random noise; do not over-read single-phase changes.
A18: Recommendations (each tied to a metric)
A19: Deployment frequency -> keep changes small; auto-merge digest-bump PRs once Cosign signature and SLSA provenance verify (removes the last manual hand-off).
A20: Lead time -> small PRs, trunk-based development and a PR review SLA; the p90 lead time (Metrics row 11) is several times the median, so the slowest changes - not the typical one - are the next target.
A21: Change failure rate -> policy-as-code on manifests/config and automated migration tests (the two largest failure categories); canary releases with Argo Rollouts gated on the SLO metrics.
A22: Recovery time -> make git-revert rollback the default remediation (fastest in Failure_Analysis); trigger it from the fast-burn SLO alert runbook.
A24: Independent calculation checks | C24: =Checks!B3 -> ALL CHECKS PASS

Sheet Raw_Data
A1: deployment_id | B1: deployed_at_utc | C1: deploy_date | D1: phase | E1: deploy_method | F1: service | G1: environment | H1: commit_sha | I1: pr_number | J1: first_commit_at_utc | K1: lead_time_hours | L1: change_failed | M1: failure_category | N1: incident_id | O1: restored_at_utc | P1: recovery_minutes | Q1: remediation | R1: manual_toil_minutes
A2: DEP-0001 | B2: 46204.857 | C2: 46204 | D2: 1-Manual | E2: manual_script | F2: healthqueue-api | G2: production (synthetic) | H2: 08c177db2761 | I2: 413 | J2: 46203.092 | K2: 42.35 | L2: FALSE | R2: 36
A3: DEP-0002 | B3: 46204.948 | C3: 46204 | D3: 1-Manual | E3: manual_script | F3: healthqueue-api | G3: production (synthetic) | H3: 8555b8a3db44 | I3: 415 | J3: 46203.405 | K3: 37.04 | L3: FALSE | R3: 53
A4: DEP-0003 | B4: 46205.572 | C4: 46205 | D4: 1-Manual | E4: manual_script | F4: healthqueue-api | G4: production (synthetic) | H4: 9d8c8e1a4fae | I4: 417 | J4: 46195.55 | K4: 240.54 | L4: TRUE | M4: configuration error | N4: INC-001 | O4: 46205.698 | P4: 181 | Q4: hotfix | R4: 48
A5: DEP-0004 | B5: 46205.954 | C5: 46205 | D5: 1-Manual | E5: manual_script | F5: healthqueue-api | G5: production (synthetic) | H5: eb7d33fa01e7 | I5: 419 | J5: 46204.948 | K5: 24.16 | L5: FALSE | R5: 42
A6: DEP-0005 | B6: 46208.704 | C6: 46208 | D6: 1-Manual | E6: manual_script | F6: healthqueue-api | G6: production (synthetic) | H6: c33e1c643710 | I6: 422 | J6: 46206.114 | K6: 62.16 | L6: FALSE | R6: 45
A7: DEP-0006 | B7: 46209.803 | C7: 46209 | D7: 1-Manual | E7: manual_script | F7: healthqueue-api | G7: production (synthetic) | H7: fcb580aeda6d | I7: 423 | J7: 46207.403 | K7: 57.6 | L7: FALSE | R7: 56
A8: DEP-0007 | B8: 46210.585 | C8: 46210 | D8: 1-Manual | E8: manual_script | F8: healthqueue-api | G8: production (synthetic) | H8: 8269fc99dbee | I8: 424 | J8: 46206.828 | K8: 90.17 | L8: FALSE | R8: 40
A9: DEP-0008 | B9: 46210.811 | C9: 46210 | D9: 1-Manual | E9: manual_script | F9: healthqueue-api | G9: production (synthetic) | H9: 5c25619cb973 | I9: 425 | J9: 46206.59 | K9: 101.31 | L9: FALSE | R9: 59
A10: DEP-0009 | B10: 46212.803 | C10: 46212 | D10: 1-Manual | E10: manual_script | F10: healthqueue-api | G10: production (synthetic) | H10: ec5a6ea4e757 | I10: 426 | J10: 46210.696 | K10: 50.57 | L10: FALSE | R10: 49
A11: DEP-0010 | B11: 46212.838 | C11: 46212 | D11: 1-Manual | E11: manual_script | F11: healthqueue-api | G11: production (synthetic) | H11: d409e92a3e31 | I11: 429 | J11: 46211.865 | K11: 23.35 | L11: FALSE | R11: 56
A12: DEP-0011 | B12: 46216.702 | C12: 46216 | D12: 1-Manual | E12: manual_script | F12: healthqueue-api | G12: production (synthetic) | H12: 1be300f59a20 | I12: 431 | J12: 46214.435 | K12: 54.42 | L12: TRUE | M12: dependency / migration | N12: INC-002 | O12: 46216.808 | P12: 153 | Q12: manual rollback | R12: 54
A13: DEP-0012 | B13: 46218.682 | C13: 46218 | D13: 1-Manual | E13: manual_script | F13: healthqueue-api | G13: production (synthetic) | H13: 223146d9aa0c | I13: 434 | J13: 46214.926 | K13: 90.15 | L13: FALSE | R13: 42
A14: DEP-0013 | B14: 46219.776 | C14: 46219 | D14: 1-Manual | E14: manual_script | F14: healthqueue-api | G14: production (synthetic) | H14: 4539b0681d9b | I14: 437 | J14: 46218.278 | K14: 35.97 | L14: FALSE | R14: 42
A15: DEP-0014 | B15: 46220.808 | C15: 46220 | D15: 1-Manual | E15: manual_script | F15: healthqueue-api | G15: production (synthetic) | H15: 3a7eb4f41dd8 | I15: 439 | J15: 46220.279 | K15: 12.68 | L15: FALSE | R15: 56
A16: DEP-0015 | B16: 46221.817 | C16: 46221 | D16: 1-Manual | E16: manual_script | F16: healthqueue-api | G16: production (synthetic) | H16: 33eea2a25ffc | I16: 442 | J16: 46219.992 | K16: 43.79 | L16: FALSE | R16: 48
A17: DEP-0016 | B17: 46224.549 | C17: 46224 | D17: 1-Manual | E17: manual_script | F17: healthqueue-api | G17: production (synthetic) | H17: 22ef8c1e2861 | I17: 443 | J17: 46222.063 | K17: 59.66 | L17: TRUE | M17: configuration error | N17: INC-003 | O17: 46224.912 | P17: 522 | Q17: hotfix | R17: 53
A18: DEP-0017 | B18: 46224.934 | C18: 46224 | D18: 1-Manual | E18: manual_script | F18: healthqueue-api | G18: production (synthetic) | H18: 1e46ad7bed18 | I18: 445 | J18: 46224.179 | K18: 18.13 | L18: TRUE | M18: dependency / migration | N18: INC-004 | O18: 46225.37 | P18: 628 | Q18: manual rollback | R18: 56
A19: DEP-0018 | B19: 46225.654 | C19: 46225 | D19: 1-Manual | E19: manual_script | F19: healthqueue-api | G19: production (synthetic) | H19: 3c9c1f284239 | I19: 448 | J19: 46224.119 | K19: 36.84 | L19: FALSE | R19: 56
A20: DEP-0019 | B20: 46227.542 | C20: 46227 | D20: 1-Manual | E20: manual_script | F20: healthqueue-api | G20: production (synthetic) | H20: 6c42eb0a2265 | I20: 451 | J20: 46226.545 | K20: 23.93 | L20: TRUE | M20: application bug (5xx) | N20: INC-005 | O20: 46227.606 | P20: 92 | Q20: manual rollback | R20: 56
A21: DEP-0020 | B21: 46227.568 | C21: 46227 | D21: 1-Manual | E21: manual_script | F21: healthqueue-api | G21: production (synthetic) | H21: 776eaba51cc5 | I21: 453 | J21: 46225.586 | K21: 47.57 | L21: FALSE | R21: 44
A22: DEP-0021 | B22: 46227.651 | C22: 46227 | D22: 1-Manual | E22: manual_script | F22: healthqueue-api | G22: production (synthetic) | H22: 2c89400b1845 | I22: 456 | J22: 46222.544 | K22: 122.57 | L22: FALSE | R22: 58
A23: DEP-0022 | B23: 46227.822 | C23: 46227 | D23: 1-Manual | E23: manual_script | F23: healthqueue-api | G23: production (synthetic) | H23: a5ba4643b1fa | I23: 458 | J23: 46226.573 | K23: 29.99 | L23: FALSE | R23: 60
A24: DEP-0023 | B24: 46230.582 | C24: 46230 | D24: 1-Manual | E24: manual_script | F24: healthqueue-api | G24: production (synthetic) | H24: d15ebfe9cc59 | I24: 461 | J24: 46229.953 | K24: 15.1 | L24: FALSE | R24: 53
A25: DEP-0024 | B25: 46231.67 | C25: 46231 | D25: 1-Manual | E25: manual_script | F25: healthqueue-api | G25: production (synthetic) | H25: 367dc28cff12 | I25: 463 | J25: 46230.524 | K25: 27.5 | L25: FALSE | R25: 56
A26: DEP-0025 | B26: 46231.733 | C26: 46231 | D26: 1-Manual | E26: manual_script | F26: healthqueue-api | G26: production (synthetic) | H26: 1a83472bf931 | I26: 466 | J26: 46227.685 | K26: 97.15 | L26: FALSE | R26: 45
A27: DEP-0026 | B27: 46232.621 | C27: 46232 | D27: 1-Manual | E27: manual_script | F27: healthqueue-api | G27: production (synthetic) | H27: cd502b24776a | I27: 468 | J27: 46228.723 | K27: 93.56 | L27: TRUE | M27: application bug (5xx) | N27: INC-006 | O27: 46232.776 | P27: 224 | Q27: manual rollback | R27: 48
A28: DEP-0027 | B28: 46232.946 | C28: 46232 | D28: 1-Manual | E28: manual_script | F28: healthqueue-api | G28: production (synthetic) | H28: 0c52133a221e | I28: 469 | J28: 46229.701 | K28: 77.88 | L28: TRUE | M28: configuration error | N28: INC-007 | O28: 46233.265 | P28: 459 | Q28: manual rollback | R28: 38
A29: DEP-0028 | B29: 46233.58 | C29: 46233 | D29: 1-Manual | E29: manual_script | F29: healthqueue-api | G29: production (synthetic) | H29: b6c20ab37fef | I29: 471 | J29: 46232.229 | K29: 32.41 | L29: FALSE | R29: 44
A30: DEP-0029 | B30: 46233.647 | C30: 46233 | D30: 1-Manual | E30: manual_script | F30: healthqueue-api | G30: production (synthetic) | H30: efcb8fbacb9f | I30: 472 | J30: 46232.743 | K30: 21.71 | L30: FALSE | R30: 53
A31: DEP-0030 | B31: 46237.546 | C31: 46237 | D31: 2-CI | E31: ci_pipeline_manual_deploy | F31: healthqueue-api | G31: production (synthetic) | H31: 21852890392a | I31: 474 | J31: 46235.278 | K31: 54.42 | L31: FALSE | R31: 26
A32: DEP-0031 | B32: 46237.687 | C32: 46237 | D32: 2-CI | E32: ci_pipeline_manual_deploy | F32: healthqueue-api | G32: production (synthetic) | H32: 4f0c58a6afb9 | I32: 477 | J32: 46237.305 | K32: 9.17 | L32: FALSE | R32: 18
A33: DEP-0032 | B33: 46237.826 | C33: 46237 | D33: 2-CI | E33: ci_pipeline_manual_deploy | F33: healthqueue-api | G33: production (synthetic) | H33: 3e8bee7168a0 | I33: 479 | J33: 46236.08 | K33: 41.9 | L33: FALSE | R33: 30
A34: DEP-0033 | B34: 46238.667 | C34: 46238 | D34: 2-CI | E34: ci_pipeline_manual_deploy | F34: healthqueue-api | G34: production (synthetic) | H34: 6166bc3dab0f | I34: 480 | J34: 46233.954 | K34: 113.11 | L34: FALSE | R34: 18
A35: DEP-0034 | B35: 46238.667 | C35: 46238 | D35: 2-CI | E35: ci_pipeline_manual_deploy | F35: healthqueue-api | G35: production (synthetic) | H35: 0c32f4178981 | I35: 482 | J35: 46237.869 | K35: 19.15 | L35: TRUE | M35: dependency / migration | N35: INC-008 | O35: 46238.705 | P35: 55 | Q35: hotfix | R35: 17
A36: DEP-0035 | B36: 46238.827 | C36: 46238 | D36: 2-CI | E36: ci_pipeline_manual_deploy | F36: healthqueue-api | G36: production (synthetic) | H36: 8b9fbe1acea0 | I36: 485 | J36: 46238.338 | K36: 11.75 | L36: FALSE | R36: 16
A37: DEP-0036 | B37: 46238.847 | C37: 46238 | D37: 2-CI | E37: ci_pipeline_manual_deploy | F37: healthqueue-api | G37: production (synthetic) | H37: 641392c4773a | I37: 487 | J37: 46237.705 | K37: 27.41 | L37: FALSE | R37: 16
A38: DEP-0037 | B38: 46239.701 | C38: 46239 | D38: 2-CI | E38: ci_pipeline_manual_deploy | F38: healthqueue-api | G38: production (synthetic) | H38: 8f146b1bff65 | I38: 488 | J38: 46239.467 | K38: 5.62 | L38: FALSE | R38: 25
A39: DEP-0038 | B39: 46240.633 | C39: 46240 | D39: 2-CI | E39: ci_pipeline_manual_deploy | F39: healthqueue-api | G39: production (synthetic) | H39: a092bfc5d7b7 | I39: 491 | J39: 46240.261 | K39: 8.93 | L39: FALSE | R39: 20
A40: DEP-0039 | B40: 46240.672 | C40: 46240 | D40: 2-CI | E40: ci_pipeline_manual_deploy | F40: healthqueue-api | G40: production (synthetic) | H40: 954d76e073ec | I40: 493 | J40: 46239.31 | K40: 32.68 | L40: FALSE | R40: 30
...

Sheet Metrics
A1: DORA metrics - calculated from Raw_Data
A2: Overall 90-day window and per 30-day phase. All cells are formulas.
A3: SYNTHETIC dataset - simulated for the assignment, not real HealthQueue production data.
C4: Period start | D4: 46204 | E4: Period end | F4: 46293
A5: Metric | B5: Unit | C5: Overall (90 d) | D5: 1-Manual | E5: 2-CI | F5: 3-GitOps | G5: How it is calculated
A6: Days in window | B6: days | C6: 90 | D6: 30 | E6: 30 | F6: 30 | G6: Input: 90-day window = three 30-day phases.
A7: Deployments | B7: count | C7: =COUNTA(DeploymentId) -> 124 | D7: =COUNTIF(Phase,D$5) -> 29 | E7: =COUNTIF(Phase,E$5) -> 34 | F7: =COUNTIF(Phase,F$5) -> 61 | G7: COUNTA / COUNTIF over Raw_Data.
A8: Deployment frequency | B8: deploys/day | C8: =C7/C6 -> 1.3777778 | D8: =D7/D6 -> 0.96666667 | E8: =E7/E6 -> 1.1333333 | F8: =F7/F6 -> 2.0333333 | G8: Deployments / days in window.
A9: Deployment frequency | B9: deploys/week | C9: =C8*7 -> 9.6444444 | D9: =D8*7 -> 6.7666667 | E9: =E8*7 -> 7.9333333 | F9: =F8*7 -> 14.233333 | G9: Deploys per day x 7.
A10: Change lead time (median) | B10: hours | C10: =MEDIAN(LeadTimeHours) -> 12.86 | D10: {=MEDIAN(IF(Phase=D$5,LeadTimeHours))} -> 43.79 | E10: {=MEDIAN(IF(Phase=E$5,LeadTimeHours))} -> 22.205 | F10: {=MEDIAN(IF(Phase=F$5,LeadTimeHours))} -> 7.51 | G10: Median of (deployed_at - first_commit_at). Median resists outliers.
A11: Change lead time (90th percentile) | B11: hours | C11: =PERCENTILE(LeadTimeHours,0.9) -> 59.042 | D11: {=PERCENTILE(IF(Phase=D$5,LeadTimeHours),0.9)} -> 97.982 | E11: {=PERCENTILE(IF(Phase=E$5,LeadTimeHours),0.9)} -> 53.154 | F11: {=PERCENTILE(IF(Phase=F$5,LeadTimeHours),0.9)} -> 13.29 | G11: Slowest 10% of changes take at least this long.
A12: Failed deployments | B12: count | C12: =COUNTIF(ChangeFailed,TRUE) -> 14 | D12: =COUNTIFS(Phase,D$5,ChangeFailed,TRUE) -> 7 | E12: =COUNTIFS(Phase,E$5,ChangeFailed,TRUE) -> 2 | F12: =COUNTIFS(Phase,F$5,ChangeFailed,TRUE) -> 5 | G12: Deployments that caused a production failure needing rollback/hotfix.
A13: Change failure rate | B13: % | C13: =C12/C7 -> 0.11290323 | D13: =D12/D7 -> 0.24137931 | E13: =E12/E7 -> 0.058823529 | F13: =F12/F7 -> 0.081967213 | G13: Failed deployments / deployments.
A14: Failed deployment recovery time (median) | B14: minutes | C14: {=MEDIAN(IF(ChangeFailed=TRUE,RecoveryMinutes))} -> 79 | D14: {=MEDIAN(IF((Phase=D$5)*(ChangeFailed=TRUE),RecoveryMinutes))} -> 224 | E14: {=MEDIAN(IF((Phase=E$5)*(ChangeFailed=TRUE),RecoveryMinutes))} -> 56.5 | F14: {=MEDIAN(IF((Phase=F$5)*(ChangeFailed=TRUE),RecoveryMinutes))} -> 36 | G14: Median of (restored_at - deployed_at) for failed deployments.
A15: Failed deployment recovery time (mean) | B15: minutes | C15: =AVERAGEIFS(RecoveryMinutes,ChangeFailed,TRUE) -> 184.5 | D15: =AVERAGEIFS(RecoveryMinutes,Phase,D$5,ChangeFailed,TRUE) -> 322.71429 | E15: =AVERAGEIFS(RecoveryMinutes,Phase,E$5,ChangeFailed,TRUE) -> 56.5 | F15: =AVERAGEIFS(RecoveryMinutes,Phase,F$5,ChangeFailed,TRUE) -> 42.2 | G15: Mean is shown to expose long-tail incidents.
A16: Manual deployment toil | B16: hours | C16: =SUM(ToilMinutes)/60 -> 40.783333 | D16: =SUMIF(Phase,D$5,ToilMinutes)/60 -> 24.1 | E16: =SUMIF(Phase,E$5,ToilMinutes)/60 -> 12.483333 | F16: =SUMIF(Phase,F$5,ToilMinutes)/60 -> 4.2 | G16: Hands-on minutes per deployment (build, deploy, smoke test, rollback), summed.
A17: Manual toil per deployment | B17: minutes | C17: =C16*60/C7 -> 19.733871 | D17: =D16*60/D7 -> 49.862069 | E17: =E16*60/E7 -> 22.029412 | F17: =F16*60/F7 -> 4.1311475 | G17: Toil / deployments.
A19: Why the median? Lead and recovery times are skewed (a few changes wait for days). The median describes the typical change; the 90th percentile and mean show the tail. Small samples (e.g. only a handful of failures per phase) make the per-phase failure rate and recovery time noisy - treat single-phase differences of a few points with caution.

Sheet Weekly_Trend
A1: Weekly trend
A2: 13 weeks (the last week has 6 days). Formulas over Raw_Data.
A3: SYNTHETIC dataset.
A5: Week | B5: Start | C5: End | D5: Deployments | E5: Deploys/day | F5: Failed | G5: Change failure rate | H5: Median lead time (h) | I5: Median recovery (min) | J5: Toil (h)
A6: 1 | B6: =Metrics!$D$4+7*(A6-1) -> 46204 | C6: =MIN(B6+6,Metrics!$F$4) -> 46210 | D6: =COUNTIFS(DeployDate,">="&B6,DeployDate,"<="&C6) -> 8 | E6: =D6/(C6-B6+1) -> 1.1428571 | F6: =COUNTIFS(DeployDate,">="&B6,DeployDate,"<="&C6,ChangeFailed,TRUE) -> 1 | G6: =IF(D6=0,"",F6/D6) -> 0.125 | H6: {=IFERROR(MEDIAN(IF((DeployDate>=B6)*(DeployDate<=C6),LeadTimeHours)),"")} -> 59.88 | I6: {=IF(F6=0,"",MEDIAN(IF((DeployDate>=B6)*(DeployDate<=C6)*(ChangeFailed=TRUE),RecoveryMinutes)))} -> 181 | J6: =SUMIFS(ToilMinutes,DeployDate,">="&B6,DeployDate,"<="&C6)/60 -> 6.3166667
A7: 2 | B7: =Metrics!$D$4+7*(A7-1) -> 46211 | C7: =MIN(B7+6,Metrics!$F$4) -> 46217 | D7: =COUNTIFS(DeployDate,">="&B7,DeployDate,"<="&C7) -> 3 | E7: =D7/(C7-B7+1) -> 0.42857143 | F7: =COUNTIFS(DeployDate,">="&B7,DeployDate,"<="&C7,ChangeFailed,TRUE) -> 1 | G7: =IF(D7=0,"",F7/D7) -> 0.33333333 | H7: {=IFERROR(MEDIAN(IF((DeployDate>=B7)*(DeployDate<=C7),LeadTimeHours)),"")} -> 50.57 | I7: {=IF(F7=0,"",MEDIAN(IF((DeployDate>=B7)*(DeployDate<=C7)*(ChangeFailed=TRUE),RecoveryMinutes)))} -> 153 | J7: =SUMIFS(ToilMinutes,DeployDate,">="&B7,DeployDate,"<="&C7)/60 -> 2.65
A8: 3 | B8: =Metrics!$D$4+7*(A8-1) -> 46218 | C8: =MIN(B8+6,Metrics!$F$4) -> 46224 | D8: =COUNTIFS(DeployDate,">="&B8,DeployDate,"<="&C8) -> 6 | E8: =D8/(C8-B8+1) -> 0.85714286 | F8: =COUNTIFS(DeployDate,">="&B8,DeployDate,"<="&C8,ChangeFailed,TRUE) -> 2 | G8: =IF(D8=0,"",F8/D8) -> 0.33333333 | H8: {=IFERROR(MEDIAN(IF((DeployDate>=B8)*(DeployDate<=C8),LeadTimeHours)),"")} -> 39.88 | I8: {=IF(F8=0,"",MEDIAN(IF((DeployDate>=B8)*(DeployDate<=C8)*(ChangeFailed=TRUE),RecoveryMinutes)))} -> 575 | J8: =SUMIFS(ToilMinutes,DeployDate,">="&B8,DeployDate,"<="&C8)/60 -> 4.95
A9: 4 | B9: =Metrics!$D$4+7*(A9-1) -> 46225 | C9: =MIN(B9+6,Metrics!$F$4) -> 46231 | D9: =COUNTIFS(DeployDate,">="&B9,DeployDate,"<="&C9) -> 8 | E9: =D9/(C9-B9+1) -> 1.1428571 | F9: =COUNTIFS(DeployDate,">="&B9,DeployDate,"<="&C9,ChangeFailed,TRUE) -> 1 | G9: =IF(D9=0,"",F9/D9) -> 0.125 | H9: {=IFERROR(MEDIAN(IF((DeployDate>=B9)*(DeployDate<=C9),LeadTimeHours)),"")} -> 33.415 | I9: {=IF(F9=0,"",MEDIAN(IF((DeployDate>=B9)*(DeployDate<=C9)*(ChangeFailed=TRUE),RecoveryMinutes)))} -> 92 | J9: =SUMIFS(ToilMinutes,DeployDate,">="&B9,DeployDate,"<="&C9)/60 -> 7.1333333
A10: 5 | B10: =Metrics!$D$4+7*(A10-1) -> 46232 | C10: =MIN(B10+6,Metrics!$F$4) -> 46238 | D10: =COUNTIFS(DeployDate,">="&B10,DeployDate,"<="&C10) -> 11 | E10: =D10/(C10-B10+1) -> 1.5714286 | F10: =COUNTIFS(DeployDate,">="&B10,DeployDate,"<="&C10,ChangeFailed,TRUE) -> 3 | G10: =IF(D10=0,"",F10/D10) -> 0.27272727 | H10: {=IFERROR(MEDIAN(IF((DeployDate>=B10)*(DeployDate<=C10),LeadTimeHours)),"")} -> 32.41 | I10: {=IF(F10=0,"",MEDIAN(IF((DeployDate>=B10)*(DeployDate<=C10)*(ChangeFailed=TRUE),RecoveryMinutes)))} -> 224 | J10: =SUMIFS(ToilMinutes,DeployDate,">="&B10,DeployDate,"<="&C10)/60 -> 5.4
A11: 6 | B11: =Metrics!$D$4+7*(A11-1) -> 46239 | C11: =MIN(B11+6,Metrics!$F$4) -> 46245 | D11: =COUNTIFS(DeployDate,">="&B11,DeployDate,"<="&C11) -> 7 | E11: =D11/(C11-B11+1) -> 1 | F11: =COUNTIFS(DeployDate,">="&B11,DeployDate,"<="&C11,ChangeFailed,TRUE) -> 0 | G11: =IF(D11=0,"",F11/D11) -> 0 | H11: {=IFERROR(MEDIAN(IF((DeployDate>=B11)*(DeployDate<=C11),LeadTimeHours)),"")} -> 17.12 | I11: {=IF(F11=0,"",MEDIAN(IF((DeployDate>=B11)*(DeployDate<=C11)*(ChangeFailed=TRUE),RecoveryMinutes)))} | J11: =SUMIFS(ToilMinutes,DeployDate,">="&B11,DeployDate,"<="&C11)/60 -> 2.5333333
A12: 7 | B12: =Metrics!$D$4+7*(A12-1) -> 46246 | C12: =MIN(B12+6,Metrics!$F$4) -> 46252 | D12: =COUNTIFS(DeployDate,">="&B12,DeployDate,"<="&C12) -> 8 | E12: =D12/(C12-B12+1) -> 1.1428571 | F12: =COUNTIFS(DeployDate,">="&B12,DeployDate,"<="&C12,ChangeFailed,TRUE) -> 0 | G12: =IF(D12=0,"",F12/D12) -> 0 | H12: {=IFERROR(MEDIAN(IF((DeployDate>=B12)*(DeployDate<=C12),LeadTimeHours)),"")} -> 17.36 | I12: {=IF(F12=0,"",MEDIAN(IF((DeployDate>=B12)*(DeployDate<=C12)*(ChangeFailed=TRUE),RecoveryMinutes)))} | J12: =SUMIFS(ToilMinutes,DeployDate,">="&B12,DeployDate,"<="&C12)/60 -> 3.1666667
A13: 8 | B13: =Metrics!$D$4+7*(A13-1) -> 46253 | C13: =MIN(B13+6,Metrics!$F$4) -> 46259 | D13: =COUNTIFS(DeployDate,">="&B13,DeployDate,"<="&C13) -> 5 | E13: =D13/(C13-B13+1) -> 0.71428571 | F13: =COUNTIFS(DeployDate,">="&B13,DeployDate,"<="&C13,ChangeFailed,TRUE) -> 1 | G13: =IF(D13=0,"",F13/D13) -> 0.2 | H13: {=IFERROR(MEDIAN(IF((DeployDate>=B13)*(DeployDate<=C13),LeadTimeHours)),"")} -> 22.35 | I13: {=IF(F13=0,"",MEDIAN(IF((DeployDate>=B13)*(DeployDate<=C13)*(ChangeFailed=TRUE),RecoveryMinutes)))} -> 58 | J13: =SUMIFS(ToilMinutes,DeployDate,">="&B13,DeployDate,"<="&C13)/60 -> 2.0166667
A14: 9 | B14: =Metrics!$D$4+7*(A14-1) -> 46260 | C14: =MIN(B14+6,Metrics!$F$4) -> 46266 | D14: =COUNTIFS(DeployDate,">="&B14,DeployDate,"<="&C14) -> 14 | E14: =D14/(C14-B14+1) -> 2 | F14: =COUNTIFS(DeployDate,">="&B14,DeployDate,"<="&C14,ChangeFailed,TRUE) -> 0 | G14: =IF(D14=0,"",F14/D14) -> 0 | H14: {=IFERROR(MEDIAN(IF((DeployDate>=B14)*(DeployDate<=C14),LeadTimeHours)),"")} -> 10.915 | I14: {=IF(F14=0,"",MEDIAN(IF((DeployDate>=B14)*(DeployDate<=C14)*(ChangeFailed=TRUE),RecoveryMinutes)))} | J14: =SUMIFS(ToilMinutes,DeployDate,">="&B14,DeployDate,"<="&C14)/60 -> 2.8666667
A15: 10 | B15: =Metrics!$D$4+7*(A15-1) -> 46267 | C15: =MIN(B15+6,Metrics!$F$4) -> 46273 | D15: =COUNTIFS(DeployDate,">="&B15,DeployDate,"<="&C15) -> 16 | E15: =D15/(C15-B15+1) -> 2.2857143 | F15: =COUNTIFS(DeployDate,">="&B15,DeployDate,"<="&C15,ChangeFailed,TRUE) -> 0 | G15: =IF(D15=0,"",F15/D15) -> 0 | H15: {=IFERROR(MEDIAN(IF((DeployDate>=B15)*(DeployDate<=C15),LeadTimeHours)),"")} -> 7.205 | I15: {=IF(F15=0,"",MEDIAN(IF((DeployDate>=B15)*(DeployDate<=C15)*(ChangeFailed=TRUE),RecoveryMinutes)))} | J15: =SUMIFS(ToilMinutes,DeployDate,">="&B15,DeployDate,"<="&C15)/60 -> 1.1833333
A16: 11 | B16: =Metrics!$D$4+7*(A16-1) -> 46274 | C16: =MIN(B16+6,Metrics!$F$4) -> 46280 | D16: =COUNTIFS(DeployDate,">="&B16,DeployDate,"<="&C16) -> 14 | E16: =D16/(C16-B16+1) -> 2 | F16: =COUNTIFS(DeployDate,">="&B16,DeployDate,"<="&C16,ChangeFailed,TRUE) -> 3 | G16: =IF(D16=0,"",F16/D16) -> 0.21428571 | H16: {=IFERROR(MEDIAN(IF((DeployDate>=B16)*(DeployDate<=C16),LeadTimeHours)),"")} -> 9.4 | I16: {=IF(F16=0,"",MEDIAN(IF((DeployDate>=B16)*(DeployDate<=C16)*(ChangeFailed=TRUE),RecoveryMinutes)))} -> 60 | J16: =SUMIFS(ToilMinutes,DeployDate,">="&B16,DeployDate,"<="&C16)/60 -> 0.88333333
A17: 12 | B17: =Metrics!$D$4+7*(A17-1) -> 46281 | C17: =MIN(B17+6,Metrics!$F$4) -> 46287 | D17: =COUNTIFS(DeployDate,">="&B17,DeployDate,"<="&C17) -> 17 | E17: =D17/(C17-B17+1) -> 2.4285714 | F17: =COUNTIFS(DeployDate,">="&B17,DeployDate,"<="&C17,ChangeFailed,TRUE) -> 1 | G17: =IF(D17=0,"",F17/D17) -> 0.058823529 | H17: {=IFERROR(MEDIAN(IF((DeployDate>=B17)*(DeployDate<=C17),LeadTimeHours)),"")} -> 6.37 | I17: {=IF(F17=0,"",MEDIAN(IF((DeployDate>=B17)*(DeployDate<=C17)*(ChangeFailed=TRUE),RecoveryMinutes)))} -> 23 | J17: =SUMIFS(ToilMinutes,DeployDate,">="&B17,DeployDate,"<="&C17)/60 -> 1.1666667
A18: 13 | B18: =Metrics!$D$4+7*(A18-1) -> 46288 | C18: =MIN(B18+6,Metrics!$F$4) -> 46293 | D18: =COUNTIFS(DeployDate,">="&B18,DeployDate,"<="&C18) -> 7 | E18: =D18/(C18-B18+1) -> 1.1666667 | F18: =COUNTIFS(DeployDate,">="&B18,DeployDate,"<="&C18,ChangeFailed,TRUE) -> 1 | G18: =IF(D18=0,"",F18/D18) -> 0.14285714 | H18: {=IFERROR(MEDIAN(IF((DeployDate>=B18)*(DeployDate<=C18),LeadTimeHours)),"")} -> 9.29 | I18: {=IF(F18=0,"",MEDIAN(IF((DeployDate>=B18)*(DeployDate<=C18)*(ChangeFailed=TRUE),RecoveryMinutes)))} -> 26 | J18: =SUMIFS(ToilMinutes,DeployDate,">="&B18,DeployDate,"<="&C18)/60 -> 0.51666667

Sheet Benchmarks
A1: Comparison with DORA 2024 performance clusters
A2: DORA (Google Cloud), Accelerate State of DevOps Report 2024 - software delivery performance clusters. https://dora.dev/research/2024/dora-report/
A4: Cluster (2024) | B4: Deployment frequency | C4: Change lead time | D4: Change failure rate | E4: Failed deployment recovery time
A5: Elite | B5: On demand (multiple deploys per day) | C5: Less than one day | D5: 0.05 | E5: Less than one hour
A6: High | B6: Between once per day and once per week | C6: Between one day and one week | D6: 0.2 | E6: Less than one day
A7: Medium | B7: Between once per week and once per month | C7: Between one week and one month | D7: 0.1 | E7: Less than one day
A8: Low | B8: Between once per month and once every six months | C8: Between one month and six months | D8: 0.4 | E8: Between one week and one month
A9: Source note: values are the 2024 report's cluster descriptions (typical values, not hard cut-offs). The 2024 Medium cluster had a LOWER change failure rate (10%) than High (20%) - the report notes this, so CFR is compared value-by-value below rather than as a strict ranking. The 2025 DORA report replaced these four tiers with seven team archetypes, so 2024 is the most recent edition with elite/high/medium/low benchmarks.
A11: Thresholds used to place a measured value in a cluster (our operationalisation)
A12: Metric | B12: Elite if | C12: High if | D12: Medium if | E12: Low otherwise / note
A13: Deployment frequency (deploys/day) | B13: 1 | C13: 0.14285714 | D13: 0.033333333 | E13: >= 1 per 6 months | F13: >= threshold
A14: Change lead time (median hours) | B14: 24 | C14: 168 | D14: 720 | E14: < 4,380 h (6 months) | F14: < threshold
A15: Change failure rate | B15: 0.05 | C15: 0.2 | D15: 0.1 | E15: <= 40% (note: Medium value < High value) | F15: <= value
A16: Recovery time (median minutes) | B16: 60 | C16: 1440 | D16: 1440 | E16: <= 43,200 min (1 month) | F16: < threshold
A18: HealthQueue (synthetic) vs. benchmarks
A19: Metric | B19: Overall (90 d) | C19: 1-Manual | D19: 2-CI | E19: 3-GitOps
A20: Deployment frequency (deploys/day) | B20: =Metrics!C8 -> 1.3777778 | C20: =Metrics!D8 -> 0.96666667 | D20: =Metrics!E8 -> 1.1333333 | E20: =Metrics!F8 -> 2.0333333
A21: -> cluster | B21: =IF(B20>=$B$13,"Elite",IF(B20>=$C$13,"High",IF(B20>=$D$13,"Medium","Low"))) -> Elite | C21: =IF(C20>=$B$13,"Elite",IF(C20>=$C$13,"High",IF(C20>=$D$13,"Medium","Low"))) -> High | D21: =IF(D20>=$B$13,"Elite",IF(D20>=$C$13,"High",IF(D20>=$D$13,"Medium","Low"))) -> Elite | E21: =IF(E20>=$B$13,"Elite",IF(E20>=$C$13,"High",IF(E20>=$D$13,"Medium","Low"))) -> Elite
A22: Change lead time (median hours) | B22: =Metrics!C10 -> 12.86 | C22: =Metrics!D10 -> 43.79 | D22: =Metrics!E10 -> 22.205 | E22: =Metrics!F10 -> 7.51
A23: -> cluster | B23: =IF(B22<$B$14,"Elite",IF(B22<$C$14,"High",IF(B22<$D$14,"Medium","Low"))) -> Elite | C23: =IF(C22<$B$14,"Elite",IF(C22<$C$14,"High",IF(C22<$D$14,"Medium","Low"))) -> High | D23: =IF(D22<$B$14,"Elite",IF(D22<$C$14,"High",IF(D22<$D$14,"Medium","Low"))) -> Elite | E23: =IF(E22<$B$14,"Elite",IF(E22<$C$14,"High",IF(E22<$D$14,"Medium","Low"))) -> Elite
A24: Change failure rate | B24: =Metrics!C13 -> 0.11290323 | C24: =Metrics!D13 -> 0.24137931 | D24: =Metrics!E13 -> 0.058823529 | E24: =Metrics!F13 -> 0.081967213
A25: -> cluster | B25: =IF(B24<=$B$15,"Elite (<=5%)",IF(B24<=$D$15,"Medium value (<=10%)",IF(B24<=$C$15,"High value (<=20%)",IF(B24<=0.4,"Low value (<=40%)","Worse than Low")))) -> High value (<=20%) | C25: =IF(C24<=$B$15,"Elite (<=5%)",IF(C24<=$D$15,"Medium value (<=10%)",IF(C24<=$C$15,"High value (<=20%)",IF(C24<=0.4,"Low value (<=40%)","Worse than Low")))) -> Low value (<=40%) | D25: =IF(D24<=$B$15,"Elite (<=5%)",IF(D24<=$D$15,"Medium value (<=10%)",IF(D24<=$C$15,"High value (<=20%)",IF(D24<=0.4,"Low value (<=40%)","Worse than Low")))) -> Medium value (<=10%) | E25: =IF(E24<=$B$15,"Elite (<=5%)",IF(E24<=$D$15,"Medium value (<=10%)",IF(E24<=$C$15,"High value (<=20%)",IF(E24<=0.4,"Low value (<=40%)","Worse than Low")))) -> Medium value (<=10%)
A26: Recovery time (median minutes) | B26: =Metrics!C14 -> 79 | C26: =Metrics!D14 -> 224 | D26: =Metrics!E14 -> 56.5 | E26: =Metrics!F14 -> 36
A27: -> cluster | B27: =IF(B26<$B$16,"Elite",IF(B26<$C$16,"High / Medium (< 1 day)",IF(B26<=43200,"Low","Worse than Low"))) -> High / Medium (< 1 day) | C27: =IF(C26<$B$16,"Elite",IF(C26<$C$16,"High / Medium (< 1 day)",IF(C26<=43200,"Low","Worse than Low"))) -> High / Medium (< 1 day) | D27: =IF(D26<$B$16,"Elite",IF(D26<$C$16,"High / Medium (< 1 day)",IF(D26<=43200,"Low","Worse than Low"))) -> Elite | E27: =IF(E26<$B$16,"Elite",IF(E26<$C$16,"High / Medium (< 1 day)",IF(E26<=43200,"Low","Worse than Low"))) -> Elite
A29: Limitations: (1) the data is SYNTHETIC; (2) DORA clusters come from survey responses about many organisations, our numbers are computed from deployment records - the measurement methods differ; (3) one service and ~30 deployments per phase is a small sample; (4) a team should compare itself mainly with its own trend, not chase a label.

Sheet Failure_Analysis
A1: What fails, and what recovers fastest
A2: Drives the toil-reduction recommendations.
A4: Failure category | B4: Failures | C4: Share of failures | D4: Median recovery (min)
A5: application bug (5xx) | B5: =COUNTIF(FailureCategory,A5) -> 3 | C5: =B5/Metrics!$C$12 -> 0.21428571 | D5: {=MEDIAN(IF(FailureCategory=A5,RecoveryMinutes))} -> 92
A6: configuration error | B6: =COUNTIF(FailureCategory,A6) -> 5 | C6: =B6/Metrics!$C$12 -> 0.35714286 | D6: {=MEDIAN(IF(FailureCategory=A6,RecoveryMinutes))} -> 181
A7: dependency / migration | B7: =COUNTIF(FailureCategory,A7) -> 5 | C7: =B7/Metrics!$C$12 -> 0.35714286 | D7: {=MEDIAN(IF(FailureCategory=A7,RecoveryMinutes))} -> 60
A8: latency regression | B8: =COUNTIF(FailureCategory,A8) -> 1 | C8: =B8/Metrics!$C$12 -> 0.071428571 | D8: {=MEDIAN(IF(FailureCategory=A8,RecoveryMinutes))} -> 36
A11: Remediation | B11: Times used | C11: Median recovery (min) | D11: Mean recovery (min)
A12: git revert (Argo CD sync) | B12: =COUNTIF(Remediation,A12) -> 4 | C12: {=MEDIAN(IF(Remediation=A12,RecoveryMinutes))} -> 31 | D12: =AVERAGEIFS(RecoveryMinutes,Remediation,A12) -> 37.75
A13: hotfix | B13: =COUNTIF(Remediation,A13) -> 3 | C13: {=MEDIAN(IF(Remediation=A13,RecoveryMinutes))} -> 181 | D13: =AVERAGEIFS(RecoveryMinutes,Remediation,A13) -> 252.66667
A14: manual rollback | B14: =COUNTIF(Remediation,A14) -> 5 | C14: {=MEDIAN(IF(Remediation=A14,RecoveryMinutes))} -> 224 | D14: =AVERAGEIFS(RecoveryMinutes,Remediation,A14) -> 311.2
A15: roll forward | B15: =COUNTIF(Remediation,A15) -> 2 | C15: {=MEDIAN(IF(Remediation=A15,RecoveryMinutes))} -> 59 | D15: =AVERAGEIFS(RecoveryMinutes,Remediation,A15) -> 59

Sheet Toil_Reduction
A1: Toil reduction - connecting the DORA results to automation
A2: Toil = manual, repetitive, automatable work that grows with deployments (Google SRE book, ch. 5).
A4: Measure | B4: 1-Manual | C4: 2-CI | D4: 3-GitOps
A5: Deployments in phase | B5: =Metrics!D7 -> 29 | C5: =Metrics!E7 -> 34 | D5: =Metrics!F7 -> 61
A6: Manual toil (hours per 30 days) | B6: =Metrics!D16 -> 24.1 | C6: =Metrics!E16 -> 12.483333 | D6: =Metrics!F16 -> 4.2
A7: Manual toil per deployment (minutes) | B7: =Metrics!D17 -> 49.862069 | C7: =Metrics!E17 -> 22.029412 | D7: =Metrics!F17 -> 4.1311475
A8: Median change lead time (hours) | B8: =Metrics!D10 -> 43.79 | C8: =Metrics!E10 -> 22.205 | D8: =Metrics!F10 -> 7.51
A9: Median recovery time (minutes) | B9: =Metrics!D14 -> 224 | C9: =Metrics!E14 -> 56.5 | D9: =Metrics!F14 -> 36
A10: Toil per deployment reduced vs. phase 1 | C10: =1-C7/$B$7 -> 0.55819299 | D10: =1-D7/$B$7 -> 0.91714849
A11: Hours saved per 30 days at phase-3 volume if phase-1 process were still used | D11: =D5*($B$7-D7)/60 -> 46.493103
A13: Toil inventory: what was automated, and what is left
A14: Manual task (phase 1) | B14: Automated by | C14: Status | D14: Effect on DORA metric
A15: Build image on a laptop, push by hand | B15: CI pipeline (.github/workflows/ci.yml, release.yml) | C15: Done | D15: Lead time: no waiting for 'the person who builds'.
A16: Manual vulnerability check / no check | B16: Trivy gate in CI + Dependabot PRs | C16: Done | D16: CFR: vulnerable images never ship.
A17: SSH/kubectl deploy script run by hand | B17: Argo CD sync from Git (GitOps) | C17: Done | D17: Deployment frequency: deploy = merge a PR.
A18: Manual rollback (find old version, redeploy) | B18: git revert -> Argo CD sync (tested: scripts/gitops_verify.sh) | C18: Done | D18: Recovery time: minutes instead of hours.
A19: Manual smoke test after each deploy | B19: Readiness probes + SLO burn-rate alerts | C19: Partly | D19: CFR/recovery: failures detected automatically.
A20: Approving each image-digest PR by hand | B20: Auto-merge digest PRs when signature + provenance verify | C20: Next | D20: Lead time: removes the remaining hand-off.
A21: Watching dashboards during rollout | B21: Progressive delivery (Argo Rollouts canary + analysis on SLIs) | C21: Next | D21: CFR: bad versions stop at 10% of traffic.
A22: Configuration mistakes reaching prod | B22: Policy-as-code tests on manifests (kubeconform + Kyverno/OPA) | C22: Partly | D22: CFR: biggest failure category (see Failure_Analysis).

Sheet Definitions
A1: Definitions, units, windows and formulas
A3: Metric | B3: DORA definition (2024) | C3: How this workbook measures it | D3: Unit | E3: Window
A4: Deployment frequency | B4: How often application changes are deployed to production. | C4: Count of production deployments / days in window. | D4: deploys per day (and per week) | E4: 90 d and 30-d phases
A5: Change lead time | B5: Time for a committed change to be successfully deployed to production. | C5: deployed_at_utc - first_commit_at_utc of the change; reported as median and p90. | D5: hours | E5: 90 d and 30-d phases
A6: Change failure rate | B6: Share of deployments that cause a failure in production requiring remediation (rollback, hotfix, roll-forward). | C6: Deployments with change_failed = TRUE / all deployments. | D6: % | E6: 90 d and 30-d phases
A7: Failed deployment recovery time | B7: Time to recover from a deployment that failed in production. | C7: restored_at_utc - deployed_at_utc for failed deployments; median and mean. | D7: minutes | E7: 90 d and 30-d phases
A8: Manual toil (supporting metric) | B8: Not a DORA metric. Google SRE definition of toil. | C8: manual_toil_minutes per deployment, summed. | D8: hours | E8: per phase
A10: Source of definitions and benchmarks: DORA (Google Cloud), Accelerate State of DevOps Report 2024 - software delivery performance clusters. https://dora.dev/research/2024/dora-report/. Synthetic data generated by scripts/generate_dora_data.py with fixed seed 20261025; the CSV is in data/dora_deployments.csv.

Sheet Checks
A1: Independent calculation checks
A2: Python recomputes each metric from the CSV; Excel formulas must match.
A3: Overall | B3: =IF(COUNTIF(E6:E80,"FAIL")=0,"ALL CHECKS PASS","CHECK FAILURES") -> ALL CHECKS PASS
A5: Check | B5: Workbook formula value | C5: Independent Python value | D5: Abs. difference | E5: Result
A6: Overall: deployments | B6: =Metrics!C7 -> 124 | C6: 124 | D6: =ABS(B6-C6) -> 0 | E6: =IF(D6<=0.000001,"PASS","FAIL") -> PASS
A7: Overall: deploys/day | B7: =Metrics!C8 -> 1.3777778 | C7: 1.3777778 | D7: =ABS(B7-C7) -> 2.220446e-16 | E7: =IF(D7<=0.000001,"PASS","FAIL") -> PASS
A8: Overall: median lead time (h) | B8: =Metrics!C10 -> 12.86 | C8: 12.86 | D8: =ABS(B8-C8) -> 0 | E8: =IF(D8<=0.000001,"PASS","FAIL") -> PASS
A9: Overall: p90 lead time (h) | B9: =Metrics!C11 -> 59.042 | C9: 59.042 | D9: =ABS(B9-C9) -> 7.1054274e-15 | E9: =IF(D9<=0.000001,"PASS","FAIL") -> PASS
A10: Overall: failed deployments | B10: =Metrics!C12 -> 14 | C10: 14 | D10: =ABS(B10-C10) -> 0 | E10: =IF(D10<=0.000001,"PASS","FAIL") -> PASS
A11: Overall: change failure rate | B11: =Metrics!C13 -> 0.11290323 | C11: 0.11290323 | D11: =ABS(B11-C11) -> 1.3877788e-17 | E11: =IF(D11<=0.000001,"PASS","FAIL") -> PASS
A12: Overall: median recovery (min) | B12: =Metrics!C14 -> 79 | C12: 79 | D12: =ABS(B12-C12) -> 0 | E12: =IF(D12<=0.000001,"PASS","FAIL") -> PASS
A13: Overall: mean recovery (min) | B13: =Metrics!C15 -> 184.5 | C13: 184.5 | D13: =ABS(B13-C13) -> 0 | E13: =IF(D13<=0.000001,"PASS","FAIL") -> PASS
A14: Overall: toil hours | B14: =Metrics!C16 -> 40.783333 | C14: 40.783333 | D14: =ABS(B14-C14) -> 0 | E14: =IF(D14<=0.000001,"PASS","FAIL") -> PASS
A15: 1-Manual: deployments | B15: =Metrics!D7 -> 29 | C15: 29 | D15: =ABS(B15-C15) -> 0 | E15: =IF(D15<=0.000001,"PASS","FAIL") -> PASS
A16: 1-Manual: deploys/day | B16: =Metrics!D8 -> 0.96666667 | C16: 0.96666667 | D16: =ABS(B16-C16) -> 0 | E16: =IF(D16<=0.000001,"PASS","FAIL") -> PASS
A17: 1-Manual: median lead time (h) | B17: =Metrics!D10 -> 43.79 | C17: 43.79 | D17: =ABS(B17-C17) -> 0 | E17: =IF(D17<=0.000001,"PASS","FAIL") -> PASS
A18: 1-Manual: p90 lead time (h) | B18: =Metrics!D11 -> 97.982 | C18: 97.982 | D18: =ABS(B18-C18) -> 0 | E18: =IF(D18<=0.000001,"PASS","FAIL") -> PASS
A19: 1-Manual: failed deployments | B19: =Metrics!D12 -> 7 | C19: 7 | D19: =ABS(B19-C19) -> 0 | E19: =IF(D19<=0.000001,"PASS","FAIL") -> PASS
A20: 1-Manual: change failure rate | B20: =Metrics!D13 -> 0.24137931 | C20: 0.24137931 | D20: =ABS(B20-C20) -> 0 | E20: =IF(D20<=0.000001,"PASS","FAIL") -> PASS
A21: 1-Manual: median recovery (min) | B21: =Metrics!D14 -> 224 | C21: 224 | D21: =ABS(B21-C21) -> 0 | E21: =IF(D21<=0.000001,"PASS","FAIL") -> PASS
A22: 1-Manual: mean recovery (min) | B22: =Metrics!D15 -> 322.71429 | C22: 322.71429 | D22: =ABS(B22-C22) -> 0 | E22: =IF(D22<=0.000001,"PASS","FAIL") -> PASS
A23: 1-Manual: toil hours | B23: =Metrics!D16 -> 24.1 | C23: 24.1 | D23: =ABS(B23-C23) -> 0 | E23: =IF(D23<=0.000001,"PASS","FAIL") -> PASS
A24: 2-CI: deployments | B24: =Metrics!E7 -> 34 | C24: 34 | D24: =ABS(B24-C24) -> 0 | E24: =IF(D24<=0.000001,"PASS","FAIL") -> PASS
A25: 2-CI: deploys/day | B25: =Metrics!E8 -> 1.1333333 | C25: 1.1333333 | D25: =ABS(B25-C25) -> 2.220446e-16 | E25: =IF(D25<=0.000001,"PASS","FAIL") -> PASS
A26: 2-CI: median lead time (h) | B26: =Metrics!E10 -> 22.205 | C26: 22.205 | D26: =ABS(B26-C26) -> 0 | E26: =IF(D26<=0.000001,"PASS","FAIL") -> PASS
A27: 2-CI: p90 lead time (h) | B27: =Metrics!E11 -> 53.154 | C27: 53.154 | D27: =ABS(B27-C27) -> 7.1054274e-15 | E27: =IF(D27<=0.000001,"PASS","FAIL") -> PASS
A28: 2-CI: failed deployments | B28: =Metrics!E12 -> 2 | C28: 2 | D28: =ABS(B28-C28) -> 0 | E28: =IF(D28<=0.000001,"PASS","FAIL") -> PASS
A29: 2-CI: change failure rate | B29: =Metrics!E13 -> 0.058823529 | C29: 0.058823529 | D29: =ABS(B29-C29) -> 6.9388939e-18 | E29: =IF(D29<=0.000001,"PASS","FAIL") -> PASS
A30: 2-CI: median recovery (min) | B30: =Metrics!E14 -> 56.5 | C30: 56.5 | D30: =ABS(B30-C30) -> 0 | E30: =IF(D30<=0.000001,"PASS","FAIL") -> PASS
A31: 2-CI: mean recovery (min) | B31: =Metrics!E15 -> 56.5 | C31: 56.5 | D31: =ABS(B31-C31) -> 0 | E31: =IF(D31<=0.000001,"PASS","FAIL") -> PASS
A32: 2-CI: toil hours | B32: =Metrics!E16 -> 12.483333 | C32: 12.483333 | D32: =ABS(B32-C32) -> 1.7763568e-15 | E32: =IF(D32<=0.000001,"PASS","FAIL") -> PASS
A33: 3-GitOps: deployments | B33: =Metrics!F7 -> 61 | C33: 61 | D33: =ABS(B33-C33) -> 0 | E33: =IF(D33<=0.000001,"PASS","FAIL") -> PASS
A34: 3-GitOps: deploys/day | B34: =Metrics!F8 -> 2.0333333 | C34: 2.0333333 | D34: =ABS(B34-C34) -> 0 | E34: =IF(D34<=0.000001,"PASS","FAIL") -> PASS
A35: 3-GitOps: median lead time (h) | B35: =Metrics!F10 -> 7.51 | C35: 7.51 | D35: =ABS(B35-C35) -> 0 | E35: =IF(D35<=0.000001,"PASS","FAIL") -> PASS
A36: 3-GitOps: p90 lead time (h) | B36: =Metrics!F11 -> 13.29 | C36: 13.29 | D36: =ABS(B36-C36) -> 0 | E36: =IF(D36<=0.000001,"PASS","FAIL") -> PASS
A37: 3-GitOps: failed deployments | B37: =Metrics!F12 -> 5 | C37: 5 | D37: =ABS(B37-C37) -> 0 | E37: =IF(D37<=0.000001,"PASS","FAIL") -> PASS
A38: 3-GitOps: change failure rate | B38: =Metrics!F13 -> 0.081967213 | C38: 0.081967213 | D38: =ABS(B38-C38) -> 0 | E38: =IF(D38<=0.000001,"PASS","FAIL") -> PASS
A39: 3-GitOps: median recovery (min) | B39: =Metrics!F14 -> 36 | C39: 36 | D39: =ABS(B39-C39) -> 0 | E39: =IF(D39<=0.000001,"PASS","FAIL") -> PASS
A40: 3-GitOps: mean recovery (min) | B40: =Metrics!F15 -> 42.2 | C40: 42.2 | D40: =ABS(B40-C40) -> 0 | E40: =IF(D40<=0.000001,"PASS","FAIL") -> PASS
A41: 3-GitOps: toil hours | B41: =Metrics!F16 -> 4.2 | C41: 4.2 | D41: =ABS(B41-C41) -> 0 | E41: =IF(D41<=0.000001,"PASS","FAIL") -> PASS
...
